Workbook

Sheet Stock_price
A1: Date | B1: XOM | C1: JNJ | D1: AMD | E1: Market index | F1: USTBILL_monthly
A2: 38352 | B2: 51.259998 | C2: 63.419998 | D2: 22.02 | E2: 100 | F2: 0.0016
A3: 38383 | B3: 51.599998 | C3: 64.699997 | D3: 15.8 | E3: 97.470955 | F3: 0.0016
A4: 38411 | B4: 63.310001 | C4: 65.599998 | D4: 17.450001 | E4: 99.313486 | F4: 0.0016
A5: 38442 | B5: 59.599998 | C5: 67.160004 | D5: 16.120001 | E5: 97.414846 | F5: 0.0021
A6: 38471 | B6: 57.029999 | C6: 68.629997 | D6: 14.23 | E6: 95.455971 | F6: 0.0021
A7: 38503 | B7: 56.200001 | C7: 67.099998 | D7: 16.4 | E7: 98.31507 | F7: 0.0024
A8: 38533 | B8: 57.470001 | C8: 65 | D8: 17.34 | E8: 98.301043 | F8: 0.0023
A9: 38562 | B9: 58.75 | C9: 63.959999 | D9: 20.08 | E9: 101.83675 | F9: 0.0024
A10: 38595 | B10: 59.900002 | C10: 63.389999 | D10: 20.77 | E10: 100.69394 | F10: 0.003
A11: 38625 | B11: 63.540001 | C11: 63.279999 | D11: 25.200001 | E11: 101.39366 | F11: 0.0029
A12: 38656 | B12: 56.139999 | C12: 62.619999 | D12: 23.219999 | E12: 99.594858 | F12: 0.0027
A13: 38686 | B13: 58.029999 | C13: 61.75 | D13: 26.18 | E13: 103.09921 | F13: 0.0031
... A242: 45657 | B242: 107.57 | C242: 144.62 | D242: 120.79 | E242: 485.31504 | F242: 0.0037

Sheet Task 1 GRAPH student 
A1: Present graph here | J1: Perform data calculations here
K3: Monthly Returns | O3: Stock Price | T3: Normalised Stock Price
K4: R_XOM | L4: R_JNJ | M4: R_AMD | O4: Date | P4: XOM | Q4: JNJ | R4: AMD | T4: XOM_norm | U4: JNJ_norm | V4: AMD_norm | W4: Market index
A5: 1. graph | K5: =(P6-P5)/P5 -> 0.0066328553 | L5: =(Q6-Q5)/Q5 -> 0.020182889 | M5: =(R6-R5)/R5 -> -0.28247049 | O5: 38352 | P5: 51.259998 | Q5: 63.419998 | R5: 22.02 | T5: =P5/$P$5*100 -> 100 | U5: =Q5/$Q$5*100 -> 100 | V5: =R5/$R$5*100 -> 100 | W5: 100
K6: =(P7-P6)/P6 -> 0.22693805 | L6: =(Q7-Q6)/Q6 -> 0.01391038 | M6: =(R7-R6)/R6 -> 0.10443041 | O6: 38383 | P6: 51.599998 | Q6: 64.699997 | R6: 15.8 | T6: =P6/$P$5*100 -> 100.66329 | U6: =Q6/$Q$5*100 -> 102.01829 | V6: =R6/$R$5*100 -> 71.752951 | W6: 97.470955
K7: =(P8-P7)/P7 -> -0.058600582 | L7: =(Q8-Q7)/Q7 -> 0.023780567 | M7: =(R8-R7)/R7 -> -0.076217757 | O7: 38411 | P7: 63.310001 | Q7: 65.599998 | R7: 17.450001 | T7: =P7/$P$5*100 -> 123.50761 | U7: =Q7/$Q$5*100 -> 103.4374 | V7: =R7/$R$5*100 -> 79.246142 | W7: 99.313486
K8: =(P9-P8)/P8 -> -0.043120801 | L8: =(Q9-Q8)/Q8 -> 0.021887932 | M8: =(R9-R8)/R8 -> -0.11724573 | O8: 38442 | P8: 59.599998 | Q8: 67.160004 | R8: 16.120001 | T8: =P8/$P$5*100 -> 116.27 | U8: =Q8/$Q$5*100 -> 105.8972 | V8: =R8/$R$5*100 -> 73.206178 | W8: 97.414846
K9: =(P10-P9)/P9 -> -0.014553709 | L9: =(Q10-Q9)/Q9 -> -0.022293441 | M9: =(R10-R9)/R9 -> 0.15249474 | O9: 38471 | P9: 57.029999 | Q9: 68.629997 | R9: 14.23 | T9: =P9/$P$5*100 -> 111.25634 | U9: =Q9/$Q$5*100 -> 108.21507 | V9: =R9/$R$5*100 -> 64.623067 | W9: 95.455971
K10: =(P11-P10)/P10 -> 0.022597873 | L10: =(Q11-Q10)/Q10 -> -0.03129655 | M10: =(R11-R10)/R10 -> 0.057317107 | O10: 38503 | P10: 56.200001 | Q10: 67.099998 | R10: 16.4 | T10: =P10/$P$5*100 -> 109.63715 | U10: =Q10/$Q$5*100 -> 105.80259 | V10: =R10/$R$5*100 -> 74.477744 | W10: 98.31507
K11: =(P12-P11)/P11 -> 0.022272468 | L11: =(Q12-Q11)/Q11 -> -0.016000014 | M11: =(R12-R11)/R11 -> 0.15801613 | O11: 38533 | P11: 57.470001 | Q11: 65 | R11: 17.34 | T11: =P11/$P$5*100 -> 112.11472 | U11: =Q11/$Q$5*100 -> 102.49133 | V11: =R11/$R$5*100 -> 78.746593 | W11: 98.301043
K12: =(P13-P12)/P12 -> 0.019574494 | L12: =(Q13-Q12)/Q12 -> -0.0089118152 | M12: =(R13-R12)/R12 -> 0.034362577 | O12: 38562 | P12: 58.75 | Q12: 63.959999 | R12: 20.08 | T12: =P12/$P$5*100 -> 114.61179 | U12: =Q12/$Q$5*100 -> 100.85147 | V12: =R12/$R$5*100 -> 91.189825 | W12: 101.83675
K13: =(P14-P13)/P13 -> 0.060767935 | L13: =(Q14-Q13)/Q13 -> -0.0017352991 | M13: =(R14-R13)/R13 -> 0.21328841 | O13: 38595 | P13: 59.900002 | Q13: 63.389999 | R13: 20.77 | T13: =P13/$P$5*100 -> 116.85525 | U13: =Q13/$Q$5*100 -> 99.952698 | V13: =R13/$R$5*100 -> 94.323343 | W13: 100.69394
K14: =(P15-P14)/P14 -> -0.11646209 | L14: =(Q15-Q14)/Q14 -> -0.010429833 | M14: =(R15-R14)/R14 -> -0.078571484 | O14: 38625 | P14: 63.540001 | Q14: 63.279999 | R14: 25.200001 | T14: =P14/$P$5*100 -> 123.95631 | U14: =Q14/$Q$5*100 -> 99.77925 | V14: =R14/$R$5*100 -> 114.44142 | W14: 101.39366
K15: =(P16-P15)/P15 -> 0.033665825 | L15: =(Q16-Q15)/Q15 -> -0.013893308 | M15: =(R16-R15)/R15 -> 0.12747636 | O15: 38656 | P15: 56.139999 | Q15: 62.619999 | R15: 23.219999 | T15: =P15/$P$5*100 -> 109.5201 | U15: =Q15/$Q$5*100 -> 98.738569 | V15: =R15/$R$5*100 -> 105.44959 | W15: 99.594858
K16: =(P17-P16)/P16 -> -0.032052398 | L16: =(Q17-Q16)/Q16 -> -0.026720672 | M16: =(R17-R16)/R16 -> 0.16883117 | O16: 38686 | P16: 58.029999 | Q16: 61.75 | R16: 26.18 | T16: =P16/$P$5*100 -> 113.20718 | U16: =Q16/$Q$5*100 -> 97.366764 | V16: =R16/$R$5*100 -> 118.89192 | W16: 103.09921
K17: =(P18-P17)/P17 -> 0.11714442 | L17: =(Q18-Q17)/Q17 -> -0.042595634 | M17: =(R18-R17)/R17 -> 0.36601303 | O17: 38716 | P17: 56.169998 | Q17: 60.099998 | R17: 30.6 | T17: =P17/$P$5*100 -> 109.57862 | U17: =Q17/$Q$5*100 -> 94.765059 | V17: =R17/$R$5*100 -> 138.96458 | W17: 103.00102
... K34: =(P35-P34)/P34 -> 0.0085367212 | L34: =(Q35-Q34)/Q34 -> -0.026078734 | M34: =(R35-R34)/R34 -> 0.0021022938 | O34: 39233 | P34: 83.169998 | Q34: 63.27 | R34: 14.27 | T34: =P34/$P$5*100 -> 162.25127 | U34: =Q34/$Q$5*100 -> 99.763485 | V34: =R34/$R$5*100 -> 64.804724 | W34: 126.29712
A35: 2. 2020-2024 | K35: =(P36-P35)/P35 -> 0.014902242 | L35: =(Q36-Q35)/Q35 -> -0.0181759 | M35: =(R36-R35)/R35 -> -0.053146868 | O35: 39262 | P35: 83.879997 | Q35: 61.619999 | R35: 14.3 | T35: =P35/$P$5*100 -> 163.63636 | U35: =Q35/$Q$5*100 -> 97.16178 | V35: =R35/$R$5*100 -> 64.940962 | W35: 124.04697
K36: =(P37-P36)/P36 -> 0.0070481161 | L36: =(Q37-Q36)/Q36 -> 0.021322329 | M36: =(R37-R36)/R36 -> -0.039881829 | O36: 39294 | P36: 85.129997 | Q36: 60.5 | R36: 13.54 | T36: =P36/$P$5*100 -> 166.07491 | U36: =Q36/$Q$5*100 -> 95.395777 | V36: =R36/$R$5*100 -> 61.489553 | W36: 120.07971
K37: =(P38-P37)/P37 -> 0.079668657 | L37: =(Q38-Q37)/Q37 -> 0.063278783 | M37: =(R38-R37)/R37 -> 0.015384601 | O37: 39325 | P37: 85.730003 | Q37: 61.790001 | R37: 13 | T37: =P37/$P$5*100 -> 167.24543 | U37: =Q37/$Q$5*100 -> 97.429837 | V37: =R37/$R$5*100 -> 59.037238 | W37: 121.62436
K38: =(P39-P38)/P38 -> -0.0061581645 | L38: =(Q39-Q38)/Q38 -> -0.0080669529 | M38: =(R39-R38)/R38 -> -0.0090909006 | O38: 39353 | P38: 92.559998 | Q38: 65.699997 | R38: 13.2 | T38: =P38/$P$5*100 -> 180.56965 | U38: =Q38/$Q$5*100 -> 103.59508 | V38: =R38/$R$5*100 -> 59.945502 | W38: 125.97779
K39: =(P40-P39)/P39 -> -0.030764151 | L39: =(Q40-Q39)/Q39 -> 0.039435319 | M39: =(R40-R39)/R39 -> -0.25382261 | O39: 39386 | P39: 91.989998 | Q39: 65.169998 | R39: 13.08 | T39: =P39/$P$5*100 -> 179.45767 | U39: =Q39/$Q$5*100 -> 102.75938 | V39: =R39/$R$5*100 -> 59.400543 | W39: 127.84507
K40: =(P41-P40)/P40 -> 0.050807521 | L40: =(Q41-Q40)/Q40 -> -0.015352834 | M40: =(R41-R40)/R40 -> -0.2315574 | O40: 39416 | P40: 89.160004 | Q40: 67.739998 | R40: 9.7600002 | T40: =P40/$P$5*100 -> 173.93681 | U40: =Q40/$Q$5*100 -> 106.81173 | V40: =R40/$R$5*100 -> 44.323343 | W40: 122.21434
K41: =(P42-P41)/P41 -> -0.077809806 | L41: =(Q42-Q41)/Q41 -> -0.053373279 | M41: =(R42-R41)/R41 -> 0.01200002 | O41: 39447 | P41: 93.690002 | Q41: 66.699997 | R41: 7.5 | T41: =P41/$P$5*100 -> 182.7741 | U41: =Q41/$Q$5*100 -> 105.17187 | V41: =R41/$R$5*100 -> 34.059945 | W41: 121.15981
K42: =(P43-P42)/P42 -> 0.0070601921 | L42: =(Q43-Q42)/Q42 -> -0.018688633 | M42: =(R43-R42)/R42 -> -0.05006589 | O42: 39478 | P42: 86.400002 | Q42: 63.139999 | R42: 7.5900002 | T42: =P42/$P$5*100 -> 168.55249 | U42: =Q42/$Q$5*100 -> 99.558501 | V42: =R42/$R$5*100 -> 34.468665 | W42: 113.74926
K43: =(P44-P43)/P43 -> -0.027927827 | L43: =(Q44-Q43)/Q43 -> 0.046965844 | M43: =(R44-R43)/R43 -> -0.18307908 | O43: 39507 | P43: 87.010002 | Q43: 61.959999 | R43: 7.21 | T43: =P43/$P$5*100 -> 169.7425 | U43: =Q43/$Q$5*100 -> 97.697888 | V43: =R43/$R$5*100 -> 32.74296 | W43: 109.7952
K44: =(P45-P44)/P44 -> 0.10037831 | L44: =(Q45-Q44)/Q44 -> 0.03422219 | M44: =(R45-R44)/R44 -> 0.011884579 | O44: 39538 | P44: 84.580002 | Q44: 64.870003 | R44: 5.8899999 | T44: =P44/$P$5*100 -> 165.00196 | U44: =Q44/$Q$5*100 -> 102.28635 | V44: =R44/$R$5*100 -> 26.748409 | W44: 109.14087
K45: =(P46-P45)/P45 -> -0.046309204 | L45: =(Q46-Q45)/Q45 -> -0.0052168504 | M45: =(R46-R45)/R45 -> 0.15436243 | O45: 39568 | P45: 93.07 | Q45: 67.089996 | R45: 5.96 | T45: =P45/$P$5*100 -> 181.56458 | U45: =Q45/$Q$5*100 -> 105.78682 | V45: =R45/$R$5*100 -> 27.066303 | W45: 114.33015
K46: =(P47-P46)/P46 -> -0.0070978466 | L46: =(Q47-Q46)/Q46 -> -0.035960468 | M46: =(R47-R46)/R46 -> -0.1526163 | O46: 39598 | P46: 88.760002 | Q46: 66.739998 | R46: 6.8800001 | T46: =P46/$P$5*100 -> 173.15647 | U46: =Q46/$Q$5*100 -> 105.23494 | V46: =R46/$R$5*100 -> 31.244323 | W46: 115.55053
K47: =(P48-P47)/P47 -> -0.087370897 | L47: =(Q48-Q47)/Q47 -> 0.064190319 | M47: =(R48-R47)/R47 -> -0.27787305 | O47: 39629 | P47: 88.129997 | Q47: 64.339996 | R47: 5.8299999 | T47: =P47/$P$5*100 -> 171.92743 | U47: =Q47/$Q$5*100 -> 101.45064 | V47: =R47/$R$5*100 -> 26.47593 | W47: 105.61753
... K51: =(P52-P51)/P51 -> 0.081354541 | L51: =(Q52-Q51)/Q51 -> -0.044995082 | M51: =(R52-R51)/R51 -> -0.32571432 | O51: 39752 | P51: 74.120003 | Q51: 61.34 | R51: 3.5 | T51: =P51/$P$5*100 -> 144.59619 | U51: =Q51/$Q$5*100 -> 96.720281 | V51: =R51/$R$5*100 -> 15.894641 | W51: 79.935144
A52: 3. Highest return | B52: XOM | C52: JNJ | D52: AMD | K52: =(P53-P52)/P52 -> -0.0039925102 | L52: =(Q53-Q52)/Q52 -> 0.02133834 | M52: =(R53-R52)/R52 -> -0.084745686 | O52: 39780 | P52: 80.150002 | Q52: 58.580002 | R52: 2.3599999 | T52: =P52/$P$5*100 -> 156.35974 | U52: =Q52/$Q$5*100 -> 92.368344 | V52: =R52/$R$5*100 -> 10.717529 | W52: 73.952076
A53: ANS: AMD | B53: =(P245-P5)/P5 -> 1.0985174 | C53: =(Q245-Q5)/Q5 -> 1.2803532 | D53: =(R245-R5)/R5 -> 4.4854677 | K53: =(P54-P53)/P53 -> -0.041964154 | L53: =(Q54-Q53)/Q53 -> -0.035768062 | M53: =(R54-R53)/R53 -> 0.013888875 | O53: 39813 | P53: 79.830002 | Q53: 59.830002 | R53: 2.1600001 | T53: =P53/$P$5*100 -> 155.73547 | U53: =Q53/$Q$5*100 -> 94.339331 | V53: =R53/$R$5*100 -> 9.8092645 | W53: 74.530497
K54: =(P55-P54)/P54 -> -0.11218621 | L54: =(Q55-Q54)/Q54 -> -0.13329864 | M54: =(R55-R54)/R54 -> -0.0045662056 | O54: 39843 | P54: 76.480003 | Q54: 57.689999 | R54: 2.1900001 | T54: =P54/$P$5*100 -> 149.20017 | U54: =Q54/$Q$5*100 -> 90.964996 | V54: =R54/$R$5*100 -> 9.9455041 | W54: 68.146412
K55: =(P56-P55)/P55 -> 0.0029454631 | L55: =(Q56-Q55)/Q55 -> 0.051999969 | M55: =(R56-R55)/R55 -> 0.3990825 | O55: 39871 | P55: 67.900002 | Q55: 50 | R55: 2.1800001 | T55: =P55/$P$5*100 -> 132.46197 | U55: =Q55/$Q$5*100 -> 78.839485 | V55: =R55/$R$5*100 -> 9.9000909 | W55: 60.654994
K56: =(P57-P56)/P56 -> -0.020998537 | L56: =(Q57-Q56)/Q56 -> -0.0045626972 | M56: =(R57-R56)/R56 -> 0.18360654 | O56: 39903 | P56: 68.099998 | Q56: 52.599998 | R56: 3.05 | T56: =P56/$P$5*100 -> 132.85213 | U56: =Q56/$Q$5*100 -> 82.939136 | V56: =R56/$R$5*100 -> 13.851044 | W56: 65.835204
K57: =(P58-P57)/P57 -> 0.040197996 | L57: =(Q58-Q57)/Q57 -> 0.053475921 | M57: =(R58-R57)/R57 -> 0.25761775 | O57: 39933 | P57: 66.669998 | Q57: 52.360001 | R57: 3.6099999 | T57: =P57/$P$5*100 -> 130.06243 | U57: =Q57/$Q$5*100 -> 82.56071 | V57: =R57/$R$5*100 -> 16.394186 | W57: 72.01878
K58: =(P59-P58)/P58 -> 0.008075057 | L58: =(Q59-Q58)/Q58 -> 0.029731679 | M58: =(R59-R58)/R58 -> -0.14757711 | O58: 39962 | P58: 69.349998 | Q58: 55.16 | R58: 4.54 | T58: =P58/$P$5*100 -> 135.29068 | U58: =Q58/$Q$5*100 -> 86.97572 | V58: =R58/$R$5*100 -> 20.61762 | W58: 75.84164
K59: =(P60-P59)/P59 -> 0.0068659091 | L59: =(Q60-Q59)/Q59 -> 0.072007046 | M59: =(R60-R59)/R59 -> -0.054263516 | O59: 39994 | P59: 69.910004 | Q59: 56.799999 | R59: 3.8699999 | T59: =P59/$P$5*100 -> 136.38316 | U59: =Q59/$Q$5*100 -> 89.561654 | V59: =R59/$R$5*100 -> 17.574931 | W59: 75.856492
K60: =(P61-P60)/P60 -> -0.017616108 | L60: =(Q61-Q60)/Q60 -> -0.0073903887 | M60: =(R61-R60)/R60 -> 0.19125684 | O60: 40025 | P60: 70.389999 | Q60: 60.889999 | R60: 3.6600001 | T60: =P60/$P$5*100 -> 137.31955 | U60: =Q60/$Q$5*100 -> 96.010724 | V60: =R60/$R$5*100 -> 16.621253 | W60: 81.480626
...

Sheet Task 2 Mean,Stdev Student
A1: Display results here | K1: Perform any calcuations here
A2: Average and standard deviation
D3: =Stock_price!B1 -> XOM | E3: =Stock_price!C1 -> JNJ | F3: =Stock_price!D1 -> AMD | G3: =Stock_price!E1 -> Market index | H3: =Stock_price!F1 -> USTBILL_monthly | K3: Monthly Returns | S3: Market index
A4: Returns | O4: USTBILL_monthly | S4: 100
B5: Arithmatic | D5: =AVERAGE(K6:K245) -> 0.0052798812 | E5: =AVERAGE(L6:L245) -> 0.0043554725 | F5: =AVERAGE(M6:M245) -> 0.021033368 | G5: =AVERAGE(N6:N245) -> 0.0075495134 | H5: =AVERAGE(O5:O245) -> 0.0012858921 | K5: R_XOM | L5: R_JNJ | M5: R_AMD | N5: R_Mkt | O5: 0.0016 | S5: 97.470955
B6: Geometric | D6: {=PRODUCT(1 + K6:K245)^(1/COUNT(K6:K245)) - 1} -> 0.0030932372 | E6: {=PRODUCT(1 + L6:L245)^(1/COUNT(L6:L245)) - 1} -> 0.0034406151 | F6: {=PRODUCT(1 + M6:M245)^(1/COUNT(M6:M245)) - 1} -> 0.0071173016 | G6: {=PRODUCT(1 + N6:N245)^(1/COUNT(N6:N245)) - 1} -> 0.0066034911 | H6: {=PRODUCT(1 + O5:O245)^(1/COUNT(O5:O245)) - 1} -> 0.0012846594 | K6: 0.0066328553 | L6: 0.020182889 | M6: -0.28247049 | N6: =S5/S4-1 -> -0.025290448 | O6: 0.0016 | P6: << Jan 2005 returns | S6: 99.313486
K7: 0.22693805 | L7: 0.01391038 | M7: 0.10443041 | N7: =S6/S5-1 -> 0.018903384 | O7: 0.0016 | S7: 97.414846
A8: Standard Deviation | D8: =_xlfn.STDEV.S(K6:K245) -> 0.066601218 | E8: =_xlfn.STDEV.S(L6:L245) -> 0.042830407 | F8: =_xlfn.STDEV.S(M6:M245) -> 0.16934011 | G8: =_xlfn.STDEV.S(N6:N245) -> 0.043307152 | H8: =_xlfn.STDEV.S(O5:O245) -> 0.0015751879 | K8: -0.058600582 | L8: 0.023780567 | M8: -0.076217757 | N8: =S7/S6-1 -> -0.019117647 | O8: 0.0021 | S8: 95.455971
K9: -0.043120801 | L9: 0.021887932 | M9: -0.11724573 | N9: =S8/S7-1 -> -0.02010859 | O9: 0.0021 | S9: 98.31507
B10: Difference | D10: =D5-D6 -> 0.002186644 | E10: =E5-E6 -> 0.00091485741 | F10: =F5-F6 -> 0.013916066 | G10: =G5-G6 -> 0.00094602229 | H10: =H5-H6 -> 1.2326987e-06 | K10: -0.014553709 | L10: -0.022293441 | M10: 0.15249474 | N10: =S9/S8-1 -> 0.029952025 | O10: 0.0024 | S10: 98.301043
K11: 0.022597873 | L11: -0.03129655 | M11: 0.057317107 | N11: =S10/S9-1 -> -0.0001426773 | O11: 0.0023 | S11: 101.83675
K12: 0.022272468 | L12: -0.016000014 | M12: 0.15801613 | N12: =S11/S10-1 -> 0.035968204 | O12: 0.0024 | S12: 100.69394
K13: 0.019574494 | L13: -0.0089118152 | M13: 0.034362577 | N13: =S12/S11-1 -> -0.011222026 | O13: 0.003 | S13: 101.39366
K14: 0.060767935 | L14: -0.0017352991 | M14: 0.21328841 | N14: =S13/S12-1 -> 0.00694894 | O14: 0.0029 | S14: 99.594858
K15: -0.11646209 | L15: -0.010429833 | M15: -0.078571484 | N15: =S14/S13-1 -> -0.017740741 | O15: 0.0027 | S15: 103.09921
K16: 0.033665825 | L16: -0.013893308 | M16: 0.12747636 | N16: =S15/S14-1 -> 0.035186121 | O16: 0.0031 | S16: 103.00102
K17: -0.032052398 | L17: -0.026720672 | M17: 0.16883117 | N17: =S16/S15-1 -> -0.0009523962 | O17: 0.0032 | S17: 105.62413
K18: 0.11714442 | L18: -0.042595634 | M18: 0.36601303 | N18: =S17/S16-1 -> 0.025466839 | O18: 0.0035 | S18: 105.67199
K19: -0.053864559 | L19: 0.0019117242 | M19: -0.07488041 | N19: =S18/S17-1 -> 0.00045309668 | O19: 0.0034 | S19: 106.84121
K20: 0.025096879 | L20: 0.027233298 | M20: -0.14248768 | N20: =S19/S18-1 -> 0.011064607 | O20: 0.0037 | S20: 108.14328
K21: 0.03647718 | L21: -0.010300584 | M21: -0.024427062 | N21: =S20/S19-1 -> 0.012186928 | O21: 0.0036 | S21: 104.79982
K22: -0.034400791 | L22: 0.027469725 | M22: -0.045131349 | N22: =S21/S20-1 -> -0.030916901 | O22: 0.0043 | S22: 104.8089
... K244: 0.010104473 | L244: -0.030339085 | M244: -0.047858707 | N244: =S243/S242-1 -> 0.057301352 | O244: 0.004 | S244: 485.31504
K245: -0.088080701 | L245: -0.067027932 | M245: -0.11944598 | N245: =S244/S243-1 -> -0.024990137 | O245: 0.0037

Sheet Task 3 Sharpe Ratio Student
A1: Display results here | J1: Perform any calcuations here
A2: Average excess returns and Sharpe Ratio | J2: Monthly Returns | Q2: Monthly Excess Returns | V2: Standard Deviation
D3: =Stock_price!B1 -> XOM | E3: =Stock_price!C1 -> JNJ | F3: =Stock_price!D1 -> AMD | G3: =Stock_price!E1 -> Market index | N3: USTBILL_monthly | Q3: XOM_excess | R3: JNJ_excess | S3: AMD_excess | T3: MKT_excess | V3: XOM | W3: JNJ | X3: AMD | Y3: MKT
J4: R_XOM | K4: R_JNJ | L4: R_AMD | M4: R_Mkt | N4: 0.0016 | Q4: =J5-N5 -> 0.0050328553 | R4: =K5-N5 -> 0.018582889 | S4: =L5-N5 -> -0.28407049 | T4: =M5-N5 -> -0.026890448 | V4: 0.066601218 | W4: 0.042830407 | X4: 0.16934011 | Y4: 0.043307152
A5: Excess Returns | D5: =AVERAGE(Q4:Q243) -> 0.0039952979 | E5: =AVERAGE(R4:R243) -> 0.0030708892 | F5: =AVERAGE(S4:S243) -> 0.019748785 | G5: =AVERAGE(T4:T243) -> 0.0062649301 | J5: 0.0066328553 | K5: 0.020182889 | L5: -0.28247049 | M5: -0.025290448 | N5: 0.0016 | O5: << Jan 2005 returns | Q5: =J6-N6 -> 0.22533805 | R5: =K6-N6 -> 0.01231038 | S5: =L6-N6 -> 0.10283041 | T5: =M6-N6 -> 0.017303384
J6: 0.22693805 | K6: 0.01391038 | L6: 0.10443041 | M6: 0.018903384 | N6: 0.0016 | Q6: =J7-N7 -> -0.060700582 | R6: =K7-N7 -> 0.021680567 | S6: =L7-N7 -> -0.078317757 | T6: =M7-N7 -> -0.021217647
A7: Sharpe Ratio | D7: =D5/V4 -> 0.05998836 | E7: =E5/W4 -> 0.07169881 | F7: =F5/X4 -> 0.11662201 | G7: =G5/Y4 -> 0.14466271 | J7: -0.058600582 | K7: 0.023780567 | L7: -0.076217757 | M7: -0.019117647 | N7: 0.0021 | Q7: =J8-N8 -> -0.045220801 | R7: =K8-N8 -> 0.019787932 | S7: =L8-N8 -> -0.11934573 | T7: =M8-N8 -> -0.02220859
J8: -0.043120801 | K8: 0.021887932 | L8: -0.11724573 | M8: -0.02010859 | N8: 0.0021 | Q8: =J9-N9 -> -0.016953709 | R8: =K9-N9 -> -0.024693441 | S8: =L9-N9 -> 0.15009474 | T8: =M9-N9 -> 0.027552025
J9: -0.014553709 | K9: -0.022293441 | L9: 0.15249474 | M9: 0.029952025 | N9: 0.0024 | Q9: =J10-N10 -> 0.020297873 | R9: =K10-N10 -> -0.03359655 | S9: =L10-N10 -> 0.055017107 | T9: =M10-N10 -> -0.0024426773
J10: 0.022597873 | K10: -0.03129655 | L10: 0.057317107 | M10: -0.0001426773 | N10: 0.0023 | Q10: =J11-N11 -> 0.019872468 | R10: =K11-N11 -> -0.018400014 | S10: =L11-N11 -> 0.15561613 | T10: =M11-N11 -> 0.033568204
J11: 0.022272468 | K11: -0.016000014 | L11: 0.15801613 | M11: 0.035968204 | N11: 0.0024 | Q11: =J12-N12 -> 0.016574494 | R11: =K12-N12 -> -0.011911815 | S11: =L12-N12 -> 0.031362577 | T11: =M12-N12 -> -0.014222026
J12: 0.019574494 | K12: -0.0089118152 | L12: 0.034362577 | M12: -0.011222026 | N12: 0.003 | Q12: =J13-N13 -> 0.057867935 | R12: =K13-N13 -> -0.0046352991 | S12: =L13-N13 -> 0.21038841 | T12: =M13-N13 -> 0.00404894
J13: 0.060767935 | K13: -0.0017352991 | L13: 0.21328841 | M13: 0.00694894 | N13: 0.0029 | Q13: =J14-N14 -> -0.11916209 | R13: =K14-N14 -> -0.013129833 | S13: =L14-N14 -> -0.081271484 | T13: =M14-N14 -> -0.020440741
J14: -0.11646209 | K14: -0.010429833 | L14: -0.078571484 | M14: -0.017740741 | N14: 0.0027 | Q14: =J15-N15 -> 0.030565825 | R14: =K15-N15 -> -0.016993308 | S14: =L15-N15 -> 0.12437636 | T14: =M15-N15 -> 0.032086121
J15: 0.033665825 | K15: -0.013893308 | L15: 0.12747636 | M15: 0.035186121 | N15: 0.0031 | Q15: =J16-N16 -> -0.035252398 | R15: =K16-N16 -> -0.029920672 | S15: =L16-N16 -> 0.16563117 | T15: =M16-N16 -> -0.0041523962
J16: -0.032052398 | K16: -0.026720672 | L16: 0.16883117 | M16: -0.0009523962 | N16: 0.0032 | Q16: =J17-N17 -> 0.11364442 | R16: =K17-N17 -> -0.046095634 | S16: =L17-N17 -> 0.36251303 | T16: =M17-N17 -> 0.021966839
J17: 0.11714442 | K17: -0.042595634 | L17: 0.36601303 | M17: 0.025466839 | N17: 0.0035 | Q17: =J18-N18 -> -0.057264559 | R17: =K18-N18 -> -0.0014882758 | S17: =L18-N18 -> -0.07828041 | T17: =M18-N18 -> -0.0029469033
J18: -0.053864559 | K18: 0.0019117242 | L18: -0.07488041 | M18: 0.00045309668 | N18: 0.0034 | Q18: =J19-N19 -> 0.021396879 | R18: =K19-N19 -> 0.023533298 | S18: =L19-N19 -> -0.14618768 | T18: =M19-N19 -> 0.0073646073
J19: 0.025096879 | K19: 0.027233298 | L19: -0.14248768 | M19: 0.011064607 | N19: 0.0037 | Q19: =J20-N20 -> 0.03287718 | R19: =K20-N20 -> -0.013900584 | S19: =L20-N20 -> -0.028027062 | T19: =M20-N20 -> 0.008586928
... J243: 0.010104473 | K243: -0.030339085 | L243: -0.047858707 | M243: 0.057301352 | N243: 0.004 | Q243: =J244-N244 -> -0.091780701 | R243: =K244-N244 -> -0.070727932 | S243: =L244-N244 -> -0.12314598 | T243: =M244-N244 -> -0.028690137
J244: -0.088080701 | K244: -0.067027932 | L244: -0.11944598 | M244: -0.024990137 | N244: 0.0037

Sheet Task 4 Cov,Corr Student
A1: Display results here | J1: Perform any calcuations here
B3: Covariance matrix | J3: Monthly Returns | N3: SD
C4: =Stock_price!B1 -> XOM | D4: =Stock_price!C1 -> JNJ | E4: =Stock_price!D1 -> AMD | J4: R_XOM | K4: R_JNJ | L4: R_AMD | N4: XOM | O4: JNJ | P4: AMD
B5: =C4 -> XOM | C5: =_xlfn.COVARIANCE.S(J5:J244, J5:J244) -> 0.0044357222 | J5: 0.0066328553 | K5: 0.020182889 | L5: -0.28247049 | N5: 0.066601218 | O5: 0.042830407 | P5: 0.16934011
B6: =D4 -> JNJ | C6: =_xlfn.COVARIANCE.S(K5:K244, J5:J244) -> 0.0010132292 | D6: =_xlfn.COVARIANCE.S(K5:K244, K5:K244) -> 0.0018344437 | J6: 0.22693805 | K6: 0.01391038 | L6: 0.10443041
B7: =E4 -> AMD | C7: =_xlfn.COVARIANCE.S(L5:L244, J5:J244) -> 0.0015301804 | D7: =_xlfn.COVARIANCE.S(L5:L244, K5:K244) -> 0.0013943638 | E7: =_xlfn.COVARIANCE.S(L5:L244, L5:L244) -> 0.028676072 | J7: -0.058600582 | K7: 0.023780567 | L7: -0.076217757
J8: -0.043120801 | K8: 0.021887932 | L8: -0.11724573
B9: Correlation matrix | J9: -0.014553709 | K9: -0.022293441 | L9: 0.15249474
C10: =C4 -> XOM | D10: =D4 -> JNJ | E10: =E4 -> AMD | J10: 0.022597873 | K10: -0.03129655 | L10: 0.057317107
B11: =B5 -> XOM | C11: =C5/(N5*N5) -> 1 | J11: 0.022272468 | K11: -0.016000014 | L11: 0.15801613
B12: =B6 -> JNJ | C12: =C6/(O5*N5) -> 0.35520029 | D12: =D6/(O5*O5) -> 1 | J12: 0.019574494 | K12: -0.0089118152 | L12: 0.034362577
B13: =B7 -> AMD | C13: =C7/(P5*N5) -> 0.13567525 | D13: =D7/(P5*O5) -> 0.19224899 | E13: =E7/(P5*P5) -> 1 | J13: 0.060767935 | K13: -0.0017352991 | L13: 0.21328841
J14: -0.11646209 | K14: -0.010429833 | L14: -0.078571484
J15: 0.033665825 | K15: -0.013893308 | L15: 0.12747636
J16: -0.032052398 | K16: -0.026720672 | L16: 0.16883117
J17: 0.11714442 | K17: -0.042595634 | L17: 0.36601303
J18: -0.053864559 | K18: 0.0019117242 | L18: -0.07488041
J19: 0.025096879 | K19: 0.027233298 | L19: -0.14248768
J20: 0.03647718 | K20: -0.010300584 | L20: -0.024427062
J21: -0.034400791 | K21: 0.027469725 | L21: -0.045131349
J22: 0.0072237503 | K22: -0.0049817842 | L22: -0.20945288
J23: 0.10415647 | K23: 0.043891875 | L23: -0.20597873
J24: -0.0010333584 | K24: 0.033733085 | L24: 0.28880869
J25: -0.0084232261 | K25: 0.0043303242 | L25: -0.0056022165
... J244: -0.088080701 | K244: -0.067027932 | L244: -0.11944598

Sheet Task 5 MV weights Student
A1: Display results here | L1: Perform any calcuations here
F2: Steps to finding optimal weights using Solver | S2: USTBILL_monthly
A3: Allow short selling, leverage | F3: step 1 | G3: Install solver | L3: Covariance matrix | S3: 0.0016
B4: Portfolio weights | M4: XOM | N4: JNJ | O4: AMD | S4: 0.0016
B5: ='Task 4 Cov,Corr Student'!C4 -> XOM | C5: ='Task 4 Cov,Corr Student'!D4 -> JNJ | D5: ='Task 4 Cov,Corr Student'!E4 -> AMD | E5: Total | F5: step 2 | G5: by changing these cells | L5: XOM | M5: 0.0044357222 | N5: 0.0010132292 | O5: 0.0015301804 | S5: 0.0016
B6: 0.23215614 | C6: 0.46401721 | D6: 0.30382666 | E6: =SUM(B6:D6) -> 1 | F6: <<<< | G6: subject to these cells equal to 1 | L6: JNJ | M6: 0.0010132292 | N6: 0.0018344437 | O6: 0.0013943638 | S6: 0.0021
L7: AMD | M7: 0.0015301804 | N7: 0.0013943638 | O7: 0.028676072 | S7: 0.0021
B8: E(rp) | C8: =(B6*O19)+(C6*P19)+(D6*Q19) -> 0.009637269 | S8: 0.0024
B9: Var(rp) | C9: =B6^2*O22^2+C6^2*P22^2+D6^2*Q22^2+2*B6*C6*N11*O22*P22+2*B6*D6*O11*O22*Q22+2*C6*D6*O12*P22*Q22 -> 0.0041084734 | L9: Correlation matrix | S9: 0.0023
M10: XOM | N10: JNJ | O10: AMD | S10: 0.0024
B11: Sharpe | C11: =(C8-L27)/SQRT(C9) -> 0.13029203 | F11: <<<< | G11: Find maximum Sharpe ratio | L11: XOM | M11: 1 | N11: 0.35520029 | O11: 0.13567525 | S11: 0.003
L12: JNJ | M12: 0.35520029 | N12: 1 | O12: 0.19224899 | S12: 0.0029
L13: AMD | M13: 0.13567525 | N13: 0.19224899 | O13: 1 | S13: 0.0027
A14: No short selling, leverage | S14: 0.0031
B15: Portfolio weights | S15: 0.0032
B16: =B5 -> XOM | C16: =C5 -> JNJ | D16: =D5 -> AMD | E16: Total | F16: Step 3 | L16: Average returns and standard deviation | S16: 0.0035
B17: 0.23215686 | C17: 0.46401676 | D17: 0.30382638 | E17: =SUM(B17:D17) -> 1 | F17: <<< | G17: constrain each weight to be | O17: XOM | P17: JNJ | Q17: AMD | S17: 0.0034
G18: => 0 and <= 1 | L18: Returns | S18: 0.0037
B19: E(rp) | C19: =(B17*O19)+(C17*P19)+(D17*Q19) -> 0.0096372649 | M19: Arithmatic | O19: 0.0052798812 | P19: 0.0043554725 | Q19: 0.021033368 | S19: 0.0036
B20: Var(rp) | C20: =B17^2*O22^2+C17^2*P22^2+D17^2*Q22^2+2*B17*C17*N11*O22*P22+2*B17*D17*O11*O22*Q22+2*C17*D17*O12*P22*Q22 -> 0.0041084694 | M20: Geometric | O20: 0.0030932372 | P20: 0.0034406151 | Q20: 0.0071173016 | S20: 0.0043
S21: 0.004
B22: Sharpe | C22: =(C19-L27)/SQRT(C20) -> 0.13029203 | L22: Standard Deviation | O22: 0.066601218 | P22: 0.042830407 | Q22: 0.16934011 | S22: 0.004
S23: 0.0042
M24: Difference | O24: 0.002186644 | P24: 0.00091485741 | Q24: 0.013916066 | S24: 0.0041
S25: 0.0041
L26: Risk-free rate | S26: 0.0042
L27: =AVERAGE(S3:S243) -> 0.0012858921 | S27: 0.004
S28: 0.0044
S29: 0.0038
S30: 0.0043
S31: 0.0044
S32: 0.0041
S33: 0.004
S34: 0.004
S35: 0.0042
S36: 0.0032
S37: 0.0032
S38: 0.0034
S39: 0.0027
... S243: 0.0037

Sheet Task 6 CAL Student
A1: Display results here | L1: Perform any calcuations here
A3: 1. Same risk as in AMD, invest in optimal portfolio and risk-free asset | L3: Optimal porfolio | N3: y
A5: Weights | B5: Risky | C5: =M21/SQRT(M10) -> 2.6419209 | L5: Portfolio weights | Q5: Risk-free rate
B6: Risk-Free | C6: =1-C5 -> -1.6419209 | L6: XOM | M6: JNJ | N6: AMD | O6: Total | Q6: 0.0012858921
L7: 0.23215686 | M7: 0.46401676 | N7: 0.30382638 | O7: 1
A8: Complete portfolio
B9: E(r) | C9: =C5*M9+C6*Q6 -> 0.023349558 | L9: E(rp) | M9: 0.0096372649
B10: StdDev | C10: =C5*SQRT(M10) -> 0.16934011 | L10: Var(rp) | M10: 0.0041084694
A12: Final allocations in the complete portfolio | L12: Sharpe | M12: 0.13029203
C13: Weights | E13: Per $10,000 invested
B14: ='Task 4 Cov,Corr Student'!C4 -> XOM | C14: =L7*C5 -> 0.61334006 | E14: =C14*10000 -> 6133.4006
B15: ='Task 4 Cov,Corr Student'!B6 -> JNJ | C15: =M7*C5 -> 1.2258956 | E15: =C15*10000 -> 12258.956 | L15: Market index
B16: ='Task 4 Cov,Corr Student'!B7 -> AMD | C16: =N7*C5 -> 0.80268524 | E16: =C16*10000 -> 8026.8524 | L16: Return | M16: 0.0075495134
L17: SD | M17: 0.043307152
B18: Risk-free | C18: =C6 -> -1.6419209 | E18: =C18*10000 -> -16419.209
L19: AMD
A20: Expected value of portfolio in 20 years, given initial investment of $10,000 | L20: Return | M20: 0.021033368
L21: SD | M21: 0.16934011
E22: Expected Value
B23: Complete Portfolio | E23: =10000*(1+C9)^(12*20) -> 2545432.1
B24: AMD | E24: =10000*(1+M20)^(12*20) -> 1477693.8
B26: Difference | E26: =E23-E24 -> 1067738.3
A28: 2. Same risk as in AMD, invest in market index and risk-free asset
A30: Weights | B30: Market index | C30: =M21/M17 -> 3.9102111
B31: Risk-Free | C31: =1-C30 -> -2.9102111
A33: Complete portfolio
B34: E(r) | C34: =C30*M16+C31*Q6 -> 0.025777974
B35: StdDev | C35: =C30*M17 -> 0.16934011
A37: Expected value of portfolio in 20 years, given initial investment of $10,000
E39: Expected Value
B40: Complete Portfolio | E40: =10000*(1+C34)^(12*20) -> 4495817.1
B41: AMD | E41: =10000*(1+M20)^(12*20) -> 1477693.8
B43: Difference | E43: =E40-E41 -> 3018123.2

Sheet Task 7 Alpha, Beta Student
A1: Display results here | L1: Perform any calcuations here | O1: (Note: Our regression tables are in the subsequent worksheets)
L2: Optimal Portfolio Weights | Q2: Risk-free rate
A3: Alpha, Beta | L3: 0.23215686 | M3: 0.46401676 | N3: 0.30382638 | Q3: 0.0012858921
C4: Optimal | D4: ='Task 2 Mean,Stdev Student'!D3 -> XOM | E4: ='Task 2 Mean,Stdev Student'!E3 -> JNJ | F4: ='Task 2 Mean,Stdev Student'!F3 -> AMD
A5: Alpha | C5: 0.001462615 | D5: -0.00085686503 | E5: -0.00043847371 | F5: 0.0061383784 | L5: Monthly Returns | P5: Monthly Excess Returns | T5: Optimal Portfolio Returns | V5: Optimal Portfolio Excess Returns | X5: Market Returns | Z5: Market Excess Returns
A6: t-stat | C6: 0.52169021 | D6: -0.22783682 | E6: -0.19003822 | F6: 0.66704832 | L6: R_XOM | M6: R_JNJ | N6: R_AMD | P6: excess_XOM | Q6: excess_JNJ | R6: excess_AMD | T6: E(rp) | V6: E(rp)-rf | X6: R_Mkt | Z6: E(rm)-rf | AB6: SUMMARY OUTPUT
L7: 0.0066328553 | M7: 0.020182889 | N7: -0.28247049 | P7: =L7-$Q$3 -> 0.0053469632 | Q7: =M7-$Q$3 -> 0.018896997 | R7: =N7-$Q$3 -> -0.28375638 | T7: =$L$3*L7+$M$3*M7+$N$3*N7 -> -0.074916923 | V7: =T7-$Q$3 -> -0.076202815 | X7: -0.025290448 | Z7: =X7-$Q$3 -> -0.02657634
A8: Beta | C8: 1.0998043 | D8: 0.77444882 | E8: 0.56006804 | F8: 2.1727203 | L8: 0.22693805 | M8: 0.01391038 | N8: 0.10443041 | P8: =L8-$Q$3 -> 0.22565216 | Q8: =M8-$Q$3 -> 0.012624488 | R8: =N8-$Q$3 -> 0.10314452 | T8: =$L$3*L8+$M$3*M8+$N$3*N8 -> 0.090868589 | V8: =T8-$Q$3 -> 0.089582697 | X8: 0.018903384 | Z8: =X8-$Q$3 -> 0.017617492 | AB8: Regression Statistics
A9: t-stat | C9: 17.130309 | D9: 8.9923113 | E9: 10.599986 | F9: 10.310378 | L9: -0.058600582 | M9: 0.023780567 | N9: -0.076217757 | P9: =L9-$Q$3 -> -0.059886474 | Q9: =M9-$Q$3 -> 0.022494675 | R9: =N9-$Q$3 -> -0.077503649 | T9: =$L$3*L9+$M$3*M9+$N$3*N9 -> -0.02572691 | V9: =T9-$Q$3 -> -0.027012803 | X9: -0.019117647 | Z9: =X9-$Q$3 -> -0.020403539 | AB9: Multiple R | AC9: 0.74307905
L10: -0.043120801 | M10: 0.021887932 | N10: -0.11724573 | P10: =L10-$Q$3 -> -0.044406693 | Q10: =M10-$Q$3 -> 0.02060204 | R10: =N10-$Q$3 -> -0.11853162 | T10: =$L$3*L10+$M$3*M10+$N$3*N10 -> -0.035476769 | V10: =T10-$Q$3 -> -0.036762661 | X10: -0.02010859 | Z10: =X10-$Q$3 -> -0.021394482 | AB10: R Square | AC10: 0.55216648
A11: R2 | C11: 0.55216648 | D11: 0.25359481 | E11: 0.32069814 | F11: 0.3087502 | L11: -0.014553709 | M11: -0.022293441 | N11: 0.15249474 | P11: =L11-$Q$3 -> -0.015839601 | Q11: =M11-$Q$3 -> -0.023579333 | R11: =N11-$Q$3 -> 0.15120885 | T11: =$L$3*L11+$M$3*M11+$N$3*N11 -> 0.032608651 | V11: =T11-$Q$3 -> 0.031322759 | X11: 0.029952025 | Z11: =X11-$Q$3 -> 0.028666133 | AB11: Adjusted R Square | AC11: 0.55028482
L12: 0.022597873 | M12: -0.03129655 | N12: 0.057317107 | P12: =L12-$Q$3 -> 0.02131198 | Q12: =M12-$Q$3 -> -0.032582442 | R12: =N12-$Q$3 -> 0.056031215 | T12: =$L$3*L12+$M$3*M12+$N$3*N12 -> 0.0081385764 | V12: =T12-$Q$3 -> 0.0068526843 | X12: -0.0001426773 | Z12: =X12-$Q$3 -> -0.0014285694 | AB12: Standard Error | AC12: 0.042984195
L13: 0.022272468 | M13: -0.016000014 | N13: 0.15801613 | P13: =L13-$Q$3 -> 0.020986576 | Q13: =M13-$Q$3 -> -0.017285906 | R13: =N13-$Q$3 -> 0.15673024 | T13: =$L$3*L13+$M$3*M13+$N$3*N13 -> 0.045755901 | V13: =T13-$Q$3 -> 0.044470009 | X13: 0.035968204 | Z13: =X13-$Q$3 -> 0.034682311 | AB13: Observations | AC13: 240
L14: 0.019574494 | M14: -0.0089118152 | N14: 0.034362577 | P14: =L14-$Q$3 -> 0.018288602 | Q14: =M14-$Q$3 -> -0.010197707 | R14: =N14-$Q$3 -> 0.033076684 | T14: =$L$3*L14+$M$3*M14+$N$3*N14 -> 0.010849379 | V14: =T14-$Q$3 -> 0.0095634865 | X14: -0.011222026 | Z14: =X14-$Q$3 -> -0.012507918
L15: 0.060767935 | M15: -0.0017352991 | N15: 0.21328841 | P15: =L15-$Q$3 -> 0.059482043 | Q15: =M15-$Q$3 -> -0.0030211912 | R15: =N15-$Q$3 -> 0.21200251 | T15: =$L$3*L15+$M$3*M15+$N$3*N15 -> 0.078105129 | V15: =T15-$Q$3 -> 0.076819237 | X15: 0.00694894 | Z15: =X15-$Q$3 -> 0.0056630479 | AB15: ANOVA
L16: -0.11646209 | M16: -0.010429833 | N16: -0.078571484 | P16: =L16-$Q$3 -> -0.11774799 | Q16: =M16-$Q$3 -> -0.011715726 | R16: =N16-$Q$3 -> -0.079857376 | T16: =$L$3*L16+$M$3*M16+$N$3*N16 -> -0.055749181 | V16: =T16-$Q$3 -> -0.057035073 | X16: -0.017740741 | Z16: =X16-$Q$3 -> -0.019026633 | AC16: df | AD16: SS | AE16: MS | AF16: F | AG16: Significance F
L17: 0.033665825 | M17: -0.013893308 | N17: 0.12747636 | P17: =L17-$Q$3 -> 0.032379933 | Q17: =M17-$Q$3 -> -0.0151792 | R17: =N17-$Q$3 -> 0.12619047 | T17: =$L$3*L17+$M$3*M17+$N$3*N17 -> 0.040099705 | V17: =T17-$Q$3 -> 0.038813813 | X17: 0.035186121 | Z17: =X17-$Q$3 -> 0.033900229 | AB17: Regression | AC17: 1 | AD17: 0.54218562 | AE17: 0.54218562 | AF17: 293.44749 | AG17: 2.1065901e-43
L18: -0.032052398 | M18: -0.026720672 | N18: 0.16883117 | P18: =L18-$Q$3 -> -0.03333829 | Q18: =M18-$Q$3 -> -0.028006565 | R18: =N18-$Q$3 -> 0.16754528 | T18: =$L$3*L18+$M$3*M18+$N$3*N18 -> 0.031455339 | V18: =T18-$Q$3 -> 0.030169447 | X18: -0.0009523962 | Z18: =X18-$Q$3 -> -0.0022382883 | AB18: Residual | AC18: 238 | AD18: 0.43973857 | AE18: 0.001847641
L19: 0.11714442 | M19: -0.042595634 | N19: 0.36601303 | P19: =L19-$Q$3 -> 0.11585853 | Q19: =M19-$Q$3 -> -0.043881526 | R19: =N19-$Q$3 -> 0.36472714 | T19: =$L$3*L19+$M$3*M19+$N$3*N19 -> 0.11863521 | V19: =T19-$Q$3 -> 0.11734931 | X19: 0.025466839 | Z19: =X19-$Q$3 -> 0.024180947 | AB19: Total | AC19: 239 | AD19: 0.98192419
L20: -0.053864559 | M20: 0.0019117242 | N20: -0.07488041 | P20: =L20-$Q$3 -> -0.055150451 | Q20: =M20-$Q$3 -> 0.00062583205 | R20: =N20-$Q$3 -> -0.076166302 | T20: =$L$3*L20+$M$3*M20+$N$3*N20 -> -0.034368599 | V20: =T20-$Q$3 -> -0.035654491 | X20: 0.00045309668 | Z20: =X20-$Q$3 -> -0.00083279543
L21: 0.025096879 | M21: 0.027233298 | N21: -0.14248768 | P21: =L21-$Q$3 -> 0.023810987 | Q21: =M21-$Q$3 -> 0.025947406 | R21: =N21-$Q$3 -> -0.14377357 | T21: =$L$3*L21+$M$3*M21+$N$3*N21 -> -0.024828396 | V21: =T21-$Q$3 -> -0.026114288 | X21: 0.011064607 | Z21: =X21-$Q$3 -> 0.0097787152 | AC21: Coefficients | AD21: Standard Error | AE21: t Stat | AF21: P-value | AG21: Lower 95% | AH21: Upper 95% | AI21: Lower 95.0% | AJ21: Upper 95.0%
L22: 0.03647718 | M22: -0.010300584 | N22: -0.024427062 | P22: =L22-$Q$3 -> 0.035191288 | Q22: =M22-$Q$3 -> -0.011586476 | R22: =N22-$Q$3 -> -0.025712954 | T22: =$L$3*L22+$M$3*M22+$N$3*N22 -> -0.0037328017 | V22: =T22-$Q$3 -> -0.0050186938 | X22: 0.012186928 | Z22: =X22-$Q$3 -> 0.010901036 | AB22: Intercept | AC22: 0.0013342774 | AD22: 0.0028166353 | AE22: 0.47371324 | AF22: 0.63613866 | AG22: -0.004214442 | AH22: 0.0068829969 | AI22: -0.004214442 | AJ22: 0.0068829969
L23: -0.034400791 | M23: 0.027469725 | N23: -0.045131349 | P23: =L23-$Q$3 -> -0.035686684 | Q23: =M23-$Q$3 -> 0.026183833 | R23: =N23-$Q$3 -> -0.046417242 | T23: =$L$3*L23+$M$3*M23+$N$3*N23 -> -0.0089520613 | V23: =T23-$Q$3 -> -0.010237953 | X23: -0.030916901 | Z23: =X23-$Q$3 -> -0.032202793 | AB23: X Variable 1 | AC23: 1.0998043 | AD23: 0.064202246 | AE23: 17.130309 | AF23: 2.1065901e-43 | AG23: 0.97332708 | AH23: 1.2262816 | AI23: 0.97332708 | AJ23: 1.2262816
L24: 0.0072237503 | M24: -0.0049817842 | N24: -0.20945288 | P24: =L24-$Q$3 -> 0.0059378581 | Q24: =M24-$Q$3 -> -0.0062676763 | R24: =N24-$Q$3 -> -0.21073877 | T24: =$L$3*L24+$M$3*M24+$N$3*N24 -> -0.064271898 | V24: =T24-$Q$3 -> -0.06555779 | X24: 8.6608036e-05 | Z24: =X24-$Q$3 -> -0.0011992841
L25: 0.10415647 | M25: 0.043891875 | N25: -0.20597873 | P25: =L25-$Q$3 -> 0.10287058 | Q25: =M25-$Q$3 -> 0.042605983 | R25: =N25-$Q$3 -> -0.20726463 | T25: =$L$3*L25+$M$3*M25+$N$3*N25 -> -0.018034567 | V25: =T25-$Q$3 -> -0.019320459 | X25: 0.0050858133 | Z25: =X25-$Q$3 -> 0.0037999211
L26: -0.0010333584 | M26: 0.033733085 | N26: 0.28880869 | P26: =L26-$Q$3 -> -0.0023192505 | Q26: =M26-$Q$3 -> 0.032447193 | R26: =N26-$Q$3 -> 0.2875228 | T26: =$L$3*L26+$M$3*M26+$N$3*N26 -> 0.10316051 | V26: =T26-$Q$3 -> 0.10187462 | X26: 0.021274263 | Z26: =X26-$Q$3 -> 0.01998837
L27: -0.0084232261 | M27: 0.0043303242 | N27: -0.0056022165 | P27: =L27-$Q$3 -> -0.0097091182 | Q27: =M27-$Q$3 -> 0.0030444321 | R27: =N27-$Q$3 -> -0.0068881086 | T27: =$L$3*L27+$M$3*M27+$N$3*N27 -> -0.0016482679 | V27: =T27-$Q$3 -> -0.00293416 | X27: 0.024566274 | Z27: =X27-$Q$3 -> 0.023280382
L28: 0.064381517 | M28: 0.037881106 | N28: -0.14406438 | P28: =L28-$Q$3 -> 0.063095625 | Q28: =M28-$Q$3 -> 0.036595213 | R28: =N28-$Q$3 -> -0.14535027 | T28: =$L$3*L28+$M$3*M28+$N$3*N28 -> -0.01124648 | V28: =T28-$Q$3 -> -0.012532372 | X28: 0.031508029 | Z28: =X28-$Q$3 -> 0.030222136
L29: 0.07546905 | M29: -0.022106793 | N29: 0.014104336 | P29: =L29-$Q$3 -> 0.074183158 | Q29: =M29-$Q$3 -> -0.023392685 | R29: =N29-$Q$3 -> 0.012818444 | T29: =$L$3*L29+$M$3*M29+$N$3*N29 -> 0.011548005 | V29: =T29-$Q$3 -> 0.010262113 | X29: 0.01646661 | Z29: =X29-$Q$3 -> 0.015180717
L30: -0.0023434489 | M30: 0.0016688359 | N30: -0.056560006 | P30: =L30-$Q$3 -> -0.003629341 | Q30: =M30-$Q$3 -> 0.00038294379 | R30: =N30-$Q$3 -> -0.057845898 | T30: =$L$3*L30+$M$3*M30+$N$3*N30 -> -0.016954102 | V30: =T30-$Q$3 -> -0.018239994 | X30: 0.012615751 | Z30: =X30-$Q$3 -> 0.011329859
L31: -0.033015775 | M31: 0.011814699 | N31: -0.23587224 | P31: =L31-$Q$3 -> -0.034301668 | Q31: =M31-$Q$3 -> 0.010528807 | R31: =N31-$Q$3 -> -0.23715813 | T31: =$L$3*L31+$M$3*M31+$N$3*N31 -> -0.073846829 | V31: =T31-$Q$3 -> -0.075132721 | X31: 0.014059085 | Z31: =X31-$Q$3 -> 0.012773193
L32: -0.032658545 | M32: -0.05793417 | N32: -0.030868199 | P32: =L32-$Q$3 -> -0.033944438 | Q32: =M32-$Q$3 -> -0.059220062 | R32: =N32-$Q$3 -> -0.032154091 | T32: =$L$3*L32+$M$3*M32+$N$3*N32 -> -0.043842904 | V32: =T32-$Q$3 -> -0.045128797 | X32: -0.021846145 | Z32: =X32-$Q$3 -> -0.023132037
L33: 0.052594819 | M33: -0.042428126 | N33: -0.13337753 | P33: =L33-$Q$3 -> 0.051308927 | Q33: =M33-$Q$3 -> -0.043714018 | R33: =N33-$Q$3 -> -0.13466342 | T33: =$L$3*L33+$M$3*M33+$N$3*N33 -> -0.048000724 | V33: =T33-$Q$3 -> -0.049286616 | X33: 0.0099799548 | Z33: =X33-$Q$3 -> 0.0086940627
L34: 0.052087481 | M34: 0.065715284 | N34: 0.058192898 | P34: =L34-$Q$3 -> 0.050801589 | Q34: =M34-$Q$3 -> 0.064429392 | R34: =N34-$Q$3 -> 0.056907006 | T34: =$L$3*L34+$M$3*M34+$N$3*N34 -> 0.060265997 | V34: =T34-$Q$3 -> 0.058980105 | X34: 0.043290683 | Z34: =X34-$Q$3 -> 0.042004791
L35: 0.047745037 | M35: -0.014792911 | N35: 0.032561561 | P35: =L35-$Q$3 -> 0.046459145 | Q35: =M35-$Q$3 -> -0.016078803 | R35: =N35-$Q$3 -> 0.031275669 | T35: =$L$3*L35+$M$3*M35+$N$3*N35 -> 0.014113241 | V35: =T35-$Q$3 -> 0.012827348 | X35: 0.032549229 | Z35: =X35-$Q$3 -> 0.031263336
... L246: -0.088080701 | M246: -0.067027932 | N246: -0.11944598 | P246: =L246-$Q$3 -> -0.089366593 | Q246: =M246-$Q$3 -> -0.068313824 | R246: =N246-$Q$3 -> -0.12073187 | T246: =$L$3*L246+$M$3*M246+$N$3*N246 -> -0.087841461 | V246: =T246-$Q$3 -> -0.089127353 | X246: -0.024990137 | Z246: =X246-$Q$3 -> -0.026276029

Sheet Task 7_Optimal
A1: SUMMARY OUTPUT | B1: Optimal Portfolio
A3: Regression Statistics
A4: Multiple R | B4: 0.74307905
A5: R Square | B5: 0.55216648
A6: Adjusted R Square | B6: 0.55028482
A7: Standard Error | B7: 0.042984195
A8: Observations | B8: 240
A10: ANOVA
B11: df | C11: SS | D11: MS | E11: F | F11: Significance F
A12: Regression | B12: 1 | C12: 0.54218562 | D12: 0.54218562 | E12: 293.44749 | F12: 2.1065901e-43
A13: Residual | B13: 238 | C13: 0.43973857 | D13: 0.001847641
A14: Total | B14: 239 | C14: 0.98192419
B16: Coefficients | C16: Standard Error | D16: t Stat | E16: P-value | F16: Lower 95% | G16: Upper 95% | H16: Lower 95.0% | I16: Upper 95.0%
A17: Intercept | B17: 0.001462615 | C17: 0.0028036083 | D17: 0.52169021 | E17: 0.60237119 | F17: -0.0040604416 | G17: 0.0069856717 | H17: -0.0040604416 | I17: 0.0069856717
A18: X Variable 1 | B18: 1.0998043 | C18: 0.064202246 | D18: 17.130309 | E18: 2.1065901e-43 | F18: 0.97332708 | G18: 1.2262816 | H18: 0.97332708 | I18: 1.2262816

Sheet Task 7_XOM
A1: SUMMARY OUTPUT | B1: XOM
A3: Regression Statistics
A4: Multiple R | B4: 0.50358198
A5: R Square | B5: 0.25359481
A6: Adjusted R Square | B6: 0.25045865
A7: Standard Error | B7: 0.057660708
A8: Observations | B8: 240
A10: ANOVA
B11: df | C11: SS | D11: MS | E11: F | F11: Significance F
A12: Regression | B12: 1 | C12: 0.26884539 | D12: 0.26884539 | E12: 80.861662 | F12: 7.7613186e-17
A13: Residual | B13: 238 | C13: 0.79129222 | D13: 0.0033247572
A14: Total | B14: 239 | C14: 1.0601376
B16: Coefficients | C16: Standard Error | D16: t Stat | E16: P-value | F16: Lower 95% | G16: Upper 95% | H16: Lower 95.0% | I16: Upper 95.0%
A17: Intercept | B17: -0.00085686503 | C17: 0.0037608717 | D17: -0.22783682 | E17: 0.81996872 | F17: -0.0082657127 | G17: 0.0065519827 | H17: -0.0082657127 | I17: 0.0065519827
A18: X Variable 1 | B18: 0.77444882 | C18: 0.086123445 | D18: 8.9923113 | E18: 7.7613186e-17 | F18: 0.60478723 | G18: 0.94411042 | H18: 0.60478723 | I18: 0.94411042

Sheet Task 7_JNJ
A1: SUMMARY OUTPUT | B1: JNJ
A3: Regression Statistics
A4: Multiple R | B4: 0.56630217
A5: R Square | B5: 0.32069814
A6: Adjusted R Square | B6: 0.31784393
A7: Standard Error | B7: 0.035374806
A8: Observations | B8: 240
A10: ANOVA
B11: df | C11: SS | D11: MS | E11: F | F11: Significance F
A12: Regression | B12: 1 | C12: 0.14060435 | D12: 0.14060435 | E12: 112.35971 | F12: 9.3727675e-22
A13: Residual | B13: 238 | C13: 0.29782771 | D13: 0.0012513769
A14: Total | B14: 239 | C14: 0.43843205
B16: Coefficients | C16: Standard Error | D16: t Stat | E16: P-value | F16: Lower 95% | G16: Upper 95% | H16: Lower 95.0% | I16: Upper 95.0%
A17: Intercept | B17: -0.00043847371 | C17: 0.0023072923 | D17: -0.19003822 | E17: 0.84944117 | F17: -0.0049837969 | G17: 0.0041068495 | H17: -0.0049837969 | I17: 0.0041068495
A18: X Variable 1 | B18: 0.56006804 | C18: 0.052836677 | D18: 10.599986 | E18: 9.3727675e-22 | F18: 0.45598077 | G18: 0.66415532 | H18: 0.45598077 | I18: 0.66415532

Sheet Task 7_AMD
A1: SUMMARY OUTPUT | B1: AMD
A3: Regression Statistics
A4: Multiple R | B4: 0.55565295
A5: R Square | B5: 0.3087502
A6: Adjusted R Square | B6: 0.30584579
A7: Standard Error | B7: 0.14108726
A8: Observations | B8: 240
A10: ANOVA
B11: df | C11: SS | D11: MS | E11: F | F11: Significance F
A12: Regression | B12: 1 | C12: 2.1160446 | D12: 2.1160446 | E12: 106.3039 | F12: 7.6032128e-21
A13: Residual | B13: 238 | C13: 4.7375367 | D13: 0.019905616
A14: Total | B14: 239 | C14: 6.8535813
B16: Coefficients | C16: Standard Error | D16: t Stat | E16: P-value | F16: Lower 95% | G16: Upper 95% | H16: Lower 95.0% | I16: Upper 95.0%
A17: Intercept | B17: 0.0061383784 | C17: 0.0092022994 | D17: 0.66704832 | E17: 0.50538745 | F17: -0.011989981 | G17: 0.024266738 | H17: -0.011989981 | I17: 0.024266738
A18: X Variable 1 | B18: 2.1727203 | C18: 0.21073139 | D18: 10.310378 | E18: 7.6032128e-21 | F18: 1.7575834 | G18: 2.5878573 | H18: 1.7575834 | I18: 2.5878573
